<?xml version='1.0' encoding='utf-8'?>
<robot name="burger">

    <link name="link0">
      <inertial>
        <origin xyz="0 0 0" rpy="0 0 0" />
        <mass value="0.0005" />
        <inertia ixx="0.0" iyy="0.0" izz="0.0" ixy="0" ixz="0" iyz="0" />
      </inertial>
    </link>
    <link name="link1">
      <inertial>
        <origin xyz="0 0 0" rpy="0 0 0" />
        <mass value="1e-10" />
        <inertia ixx="1e-10" iyy="1e-10" izz="1e-10" ixy="0" ixz="0" iyz="0" />
      </inertial>
    </link>
    <link name="link2">
      <inertial>
        <origin xyz="0 0 0" rpy="0 0 0" />
        <mass value="1e-10" />
        <inertia ixx="1e-10" iyy="1e-10" izz="1e-10" ixy="0" ixz="0" iyz="0" />
      </inertial>
      <collision>
        <origin xyz="-0.0575 -0.0575 0" rpy="0 0 0"/>
        <geometry>
          <box size="0.005 0.005 0.03846667"/>
        </geometry>
      </collision>
    </link>
    <link name="link3">
      <inertial>
        <origin xyz="0 0 0" rpy="0 0 0" />
        <mass value="1e-10" />
        <inertia ixx="1e-10" iyy="1e-10" izz="1e-10" ixy="0" ixz="0" iyz="0" />
      </inertial>
      <collision>
        <origin xyz="-0.0575 0.0575 0" rpy="0 0 0"/>
        <geometry>
          <box size="0.005 0.005 0.03846667"/>
        </geometry>
      </collision>
    </link>
      <link name="link4">
      <inertial>
        <origin xyz="0 0 0" rpy="0 0 0" />
        <mass value="1e-10" />
        <inertia ixx="1e-10" iyy="1e-10" izz="1e-10" ixy="0" ixz="0" iyz="0" />
      </inertial>
      <collision>
        <origin xyz="0.0575 -0.0575 0" rpy="0 0 0"/>
        <geometry>
          <box size="0.005 0.005 0.03846667"/>
        </geometry>
      </collision>
    </link>
    <link name="link5">
      <inertial>
        <origin xyz="0 0 0" rpy="0 0 0" />
        <mass value="1e-10" />
        <inertia ixx="1e-10" iyy="1e-10" izz="1e-10" ixy="0" ixz="0" iyz="0" />
      </inertial>
      <collision>
        <origin xyz="0.0575 0.0575 0" rpy="0 0 0"/>
        <geometry>
          <box size="0.005 0.005 0.03846667"/>
        </geometry>
      </collision>
    </link>
    <link name="link6">
      <inertial>
        <origin xyz="0 0 0" rpy="0 0 0" />
        <mass value="0.173" />
        <inertia ixx="7.821e-5" iyy="7.821e-5" izz="1.384e-4" ixy="0" ixz="0" iyz="0" />
      </inertial>
      <visual>
        <origin xyz="0 0 -0.025" rpy="0 0 0" />
        <geometry>
          <!-- <cylinder length="0.00846667" radius="0.04064"/> -->
          <mesh filename="../../../zoom-chef/kitchen_objects/meshes/collision/BurgerPrism.obj" scale="1.0 1.0 1.0"/>
        </geometry>
      </visual>

      <visual>
        <origin xyz="-0.0575 -0.0575 0" rpy="0 0 0"/>
        <geometry>
          <box size="0.005 0.005 0.03846667"/>
        </geometry>
      </visual>
      <visual>
        <origin xyz="-0.0575 0.0575 0" rpy="0 0 0"/>
        <geometry>
          <box size="0.005 0.005 0.03846667"/>
        </geometry>
      </visual>
      <visual>
        <origin xyz="0.0575 -0.0575 0" rpy="0 0 0"/>
        <geometry>
          <box size="0.005 0.005 0.03846667"/>
        </geometry>
      </visual>
      <visual>
        <origin xyz="0.0575 0.0575 0" rpy="0 0 0"/>
        <geometry>
          <box size="0.005 0.005 0.03846667"/>
        </geometry>
      </visual>

      <visual>
        <origin xyz="0 0 0" rpy="0 0 0"/>
        <geometry>
          <box size="0.08 0.08 0.00846667"/>
        </geometry>
      </visual>
      <!-- <collision>
        <origin xyz="0 0 0.0" rpy="0 0 0" />
<<<<<<< HEAD
=======
          <!-- <cylinder length="0.00846667" radius="0.04064"/> -->
>>>>>>> 1d88e25177a8cc3ac0f6997aeaca5a463956a21f
        <geometry>
          <mesh filename="../../../zoom-chef/kitchen_objects/meshes/collision/BurgerPrism.obj" scale="1.0 1.0 1.0"/>
        </geometry>
      </collision> -->

      <collision>
        <origin xyz="0 0 0" rpy="0 0 0"/>
        <geometry>
          <box size="0.08 0.08 0.00846667"/>
        </geometry>
      </collision>
    </link>
    
    <joint name="joint1" type="prismatic">
      <origin xyz="0 0 0" rpy="0 0 0"/>
      <parent link="link0"/>
      <child link="link1"/>
      <axis xyz="0 0 1"/>
      <!-- <dynamics damping="0.0" friction="1"/> -->
      <limit effort="21.3" lower="-100" upper="100" velocity="21.3"/>
    </joint>
    <joint name="joint2" type="prismatic">
      <origin xyz="0 0 0" rpy="0 0 0"/>
      <parent link="link1"/>
      <child link="link2"/>
      <axis xyz="0 1 0"/>
      <!-- <dynamics damping="0.0" friction="1"/> -->
      <limit effort="21.3" lower="-100" upper="100" velocity="21.3"/>
    </joint>
    <joint name="joint3" type="prismatic">
      <origin xyz="0 0 0" rpy="0 0 0"/>
      <parent link="link2"/>
      <child link="link3"/>
      <axis xyz="1 0 0"/>
      <limit effort="21.3" lower="-100" upper="100" velocity="21.3"/>
    </joint>
    <joint name="joint4" type="revolute">
      <origin xyz="0 0 0" rpy="0 0 0"/>
      <parent link="link3"/>
      <child link="link4"/>
        <axis xyz="1 0 0"/>
<<<<<<< HEAD
        <dynamics damping="20.0" friction="2.0"/>
=======
        <!-- <dynamics damping="0.0" friction="3"/> -->
>>>>>>> 1d88e25177a8cc3ac0f6997aeaca5a463956a21f
      <limit effort="21.3" lower="0" upper="6.28" velocity="21.3"/>
    </joint>
    <joint name="joint5" type="revolute">
      <origin xyz="0 0 0" rpy="0 0 0"/>
      <parent link="link4"/>
      <child link="link5"/>
        <axis xyz="0 1 0"/>
<<<<<<< HEAD
        <dynamics damping="20.0" friction="2.0"/>
=======
        <!-- <dynamics damping="0.0" friction="3"/> -->
>>>>>>> 1d88e25177a8cc3ac0f6997aeaca5a463956a21f
      <limit effort="21.3" lower="0" upper="6.28" velocity="21.3"/>
    </joint>
    <joint name="joint6" type="revolute">
      <origin xyz="0 0 0" rpy="0 0 0"/>
      <parent link="link5"/>
      <child link="link6"/>
        <axis xyz="0 0 1"/>
<<<<<<< HEAD
        <dynamics damping="20.0" friction="2.0"/>
=======
        <!-- <dynamics damping="0.0" friction="3"/> -->
>>>>>>> 1d88e25177a8cc3ac0f6997aeaca5a463956a21f
      <limit effort="21.3" lower="0" upper="6.28" velocity="21.3"/>
    </joint>
</robot>

</xml>
